Workbook

Sheet 本次災點比對結果
A1: 序號 | B1: 轄區科 | C1: 行政區 | D1: 淹水路段(地址) | E1: 淹水高度(公分) | F1: 深度分級 | G1: 初判結果 | H1: 表內既有判定 | I1: 定位方式 | J1: 經度X | K1: 緯度Y | L1: 名稱相符之歷史災點(項次:名稱[等級/相符路名]) | M1: 最近歷史災點 | N1: 最近距離(公尺) | O1: 權責單位 | P1: 淹水時間 | Q1: 退水時間 | R1: 通報來源
A2: 22 | B2: 雨水 | C2: 中西區 | D2: 民權路四段 & 中華西路二段 | E2: 15 | F2: 10-30 | G2: 疑似舊災點 | I2: 原始座標 | J2: 120.18658 | K2: 22.999028 | L2: #148:臨安路一段周邊巷道[中/中華西路二段] | M2: #179 民權路四段 | N2: 192.7 | P2: 2026-06-25 21:58 | Q2: 2026-06-25 22:39 | R2: 公所通報
A3: 23 | B3: 雨水 | C3: 中西區 | D3: 中正路150巷 | E3: 10 | F3: 0-10 | G3: 新災點(初判) | I3: 原始座標 | J3: 120.19929 | K3: 22.993045 | M3: #147 友愛街261號(編號100感測器) | N3: 317.8 | P3: 2026-06-25 22:00 | Q3: 2026-06-25 22:45 | R3: 轄區科通報
A4: 24 | B4: 雨水 | C4: 中西區 | D4: 頂美二街76巷 | E4: 10 | F4: 0-10 | G4: 新災點(初判) | I4: 原始座標 | J4: 120.18542 | K4: 23.00151 | M4: #179 民權路四段 | N4: 271 | P4: 2026-06-25 22:00 | Q4: 2026-06-25 22:37 | R4: 轄區科通報
A5: 25 | B5: 雨水 | C5: 中西區 | D5: 中西區-臨安路跟民權路路口(編號273) | E5: 15 | F5: 10-30 | G5: 疑似舊災點 | I5: 原始座標 | J5: 120.18972 | K5: 22.998455 | L5: #146:六合境清水寺[中/民權路] #149:臨安路一段與民權路三段路口[中/民權路、臨安路、跟民權路] | M5: #149 臨安路一段與民權路三段路口 | N5: 4 | P5: 2026-06-25 22:43 | Q5: 2026-06-25 23:13 | R5: 轄區科通報
A6: 26 | B6: 雨水 | C6: 中西區 | D6: 中華西路二段418巷7號 | E6: 20 | F6: 10-30 | G6: 待確認(路名部分相符) | I6: 原始座標 | J6: 120.18769 | K6: 23.000456 | L6: #148:臨安路一段周邊巷道[中/中華西路二段] | M6: #149 臨安路一段與民權路三段路口 | N6: 305.5 | P6: 2026-06-25 22:50 | Q6: 2026-06-25 22:50 | R6: 1999
A7: 27 | B7: 雨水 | C7: 中西區 | D7: 中西區民權路四段112巷45號 | F7: 100以上 | G7: 疑似舊災點(距離相近) | I7: 路名比對近似(民權路四段) | J7: 120.18658 | K7: 22.999028 | M7: #179 民權路四段 | N7: 192.7 | P7: 2026-06-26 04:39 | Q7: 2026-06-26 18:04 | R7: EMIC
A8: 28 | B8: 雨水 | C8: 中西區 | D8: 中西區頂美一街36巷社區 | F8: 100以上 | G8: 疑似舊災點(距離相近) | I8: 路名比對近似(中華西路) | J8: 120.19174 | K8: 23.00023 | M8: #148 臨安路一段周邊巷道 | N8: 0 | P8: 2026-06-26 07:46 | Q8: 2026-06-26 18:24 | R8: EMIC
A9: 29 | B9: 雨水 | C9: 中西區 | D9: 中西區頂美二街 | F9: 100以上 | G9: 新災點(初判) | I9: 路名比對近似(頂美二街) | J9: 120.18542 | K9: 23.00151 | M9: #179 民權路四段 | N9: 271 | P9: 2026-06-26 09:31 | Q9: 2026-06-26 18:04 | R9: EMIC
A10: 30 | B10: 雨水 | C10: 中西區 | D10: 中西區文祥街跟西和路的交叉口 | F10: 100以上 | G10: 無法定位，需人工確認 | I10: 未定位 | P10: 2026-06-26 10:43 | Q10: 2026-06-26 18:04 | R10: EMIC
A11: 31 | B11: 雨水 | C11: 中西區 | D11: 中西區府前路一段320號前 | F11: 100以上 | G11: 無法定位，需人工確認 | I11: 未定位 | P11: 115/06/26 04:26:00 AM | R11: 1999通報單
A12: 32 | B12: 雨水 | C12: 中西區 | D12: 中西區民權路四段112巷11號 | F12: 100以上 | G12: 疑似舊災點(距離相近) | I12: 路名比對近似(民權路四段) | J12: 120.18658 | K12: 22.999028 | M12: #179 民權路四段 | N12: 192.7 | P12: 115/06/26 03:50:00 AM | R12: 1999通報單
A13: 33 | B13: 雨水 | C13: 中西區 | D13: 中西區林森一街82巷30號路口 | F13: 100以上 | G13: 無法定位，需人工確認 | I13: 未定位 | P13: 115/06/26 02:58:00 AM | R13: 1999通報單
A14: 34 | B14: 雨水 | C14: 中西區 | D14: 中西區林森一街48巷3弄8號、1到3街 | F14: 100以上 | G14: 無法定位，需人工確認 | I14: 未定位 | P14: 115/06/26 02:58:00 AM | R14: 1999通報單
A15: 35 | B15: 雨水 | C15: 中西區 | D15: 中西區尊王路163號靠近環河 | F15: 100以上 | G15: 無法定位，需人工確認 | I15: 未定位 | P15: 115/06/26 05:07:00 AM | R15: 1999通報單
A16: 36 | B16: 雨水 | C16: 中西區 | D16: 中西區大興街 | F16: 100以上 | G16: 無法定位，需人工確認 | I16: 未定位 | P16: 115/06/26 04:54:00 AM | R16: 1999通報單
A17: 37 | B17: 雨水 | C17: 中西區 | D17: 中西區民權路四段112巷45號 | F17: 100以上 | G17: 疑似舊災點(距離相近) | I17: 路名比對近似(民權路四段) | J17: 120.18658 | K17: 22.999028 | M17: #179 民權路四段 | N17: 192.7 | P17: 115/06/26 04:45:00 AM | R17: 1999通報單
A18: 38 | B18: 雨水 | C18: 中西區 | D18: 中西區武聖路69巷85弄 | F18: 100以上 | G18: 無法定位，需人工確認 | I18: 未定位 | P18: 115/06/26 05:57:00 AM | R18: 1999通報單
A19: 39 | B19: 雨水 | C19: 中西區 | D19: 中西區大新街47號 | F19: 100以上 | G19: 疑似舊災點 | I19: 路名比對近似(大新街) | J19: 120.19174 | K19: 23.00023 | L19: #148:臨安路一段周邊巷道[中/大新街] #149:臨安路一段與民權路三段路口[中/大新街] | M19: #148 臨安路一段周邊巷道 | N19: 0 | P19: 115/06/25 09:33:00 PM | R19: 1999通報單
A20: 40 | B20: 雨水 | C20: 中西區 | D20: 中西區頂美一街48巷3弄8號 | F20: 100以上 | G20: 無法定位，需人工確認 | I20: 未定位 | P20: 115/06/25 09:54:00 PM | R20: 1999通報單
A21: 41 | B21: 雨水 | C21: 中西區 | D21: 中西區中華西路二段418巷7號 | F21: 100以上 | G21: 疑似舊災點 | I21: 路名比對近似(中華西路二段) | J21: 120.18658 | K21: 22.999028 | L21: #148:臨安路一段周邊巷道[中/中華西路二段] | M21: #179 民權路四段 | N21: 192.7 | P21: 115/06/25 09:57:00 PM | R21: 1999通報單
A22: 42 | B22: 雨水 | C22: 中西區 | D22: 中西區開山路52巷3號 | F22: 100以上 | G22: 疑似舊災點 | I22: 路名比對近似(開山路) | J22: 120.20634 | K22: 22.990732 | L22: #150:府中街98巷[高/開山路52巷] | M22: #150 府中街98巷 | N22: 0 | P22: 115/06/25 10:04:00 PM | R22: 1999通報單
A23: 43 | B23: 雨水 | C23: 中西區 | D23: 中西區頂美二街72巷13號 | F23: 100以上 | G23: 新災點(初判) | I23: 路名比對近似(頂美二街) | J23: 120.18542 | K23: 23.00151 | M23: #179 民權路四段 | N23: 271 | P23: 115/06/25 10:04:00 PM | R23: 1999通報單
A24: 44 | B24: 雨水 | C24: 中西區 | D24: 中西區新美街與郡緯街路口 | F24: 100以上 | G24: 無法定位，需人工確認 | I24: 未定位 | P24: 115/06/25 10:16:00 PM | R24: 1999通報單
A25: 45 | B25: 雨水 | C25: 中西區 | D25: 中西區文和街88號旁巷子 | F25: 100以上 | G25: 無法定位，需人工確認 | I25: 未定位 | P25: 115/06/25 10:30:00 PM | R25: 1999通報單
A26: 46 | B26: 雨水 | C26: 中西區 | D26: 中西區民權路四段36號 | F26: 100以上 | G26: 疑似舊災點(距離相近) | I26: 路名比對近似(民權路四段) | J26: 120.18658 | K26: 22.999028 | M26: #179 民權路四段 | N26: 192.7 | P26: 115/06/25 10:31:00 PM | R26: 1999通報單
A27: 47 | B27: 雨水 | C27: 中西區 | D27: 中西區西河路33號 | F27: 100以上 | G27: 無法定位，需人工確認 | I27: 未定位 | P27: 115/06/25 10:32:00 PM | R27: 1999通報單
A28: 48 | B28: 雨水 | C28: 中西區 | D28: 中西區民權路三段與大興街路口 | F28: 100以上 | G28: 疑似舊災點 | I28: 路名比對近似(民權路三段) | J28: 120.19174 | K28: 23.00023 | L28: #148:臨安路一段周邊巷道[中/民權路三段] #149:臨安路一段與民權路三段路口[中/民權路三段] | M28: #148 臨安路一段周邊巷道 | N28: 0 | P28: 115/06/25 10:32:00 PM | R28: 1999通報單
A29: 49 | B29: 雨水 | C29: 中西區 | D29: 中西區民生路一段169號前 | F29: 100以上 | G29: 無法定位，需人工確認 | I29: 未定位 | P29: 115/06/25 11:09:00 PM | R29: 1999通報單
A30: 50 | B30: 雨水 | C30: 中西區 | D30: 中西區民權路四段112巷45號 | F30: 100以上 | G30: 疑似舊災點(距離相近) | I30: 路名比對近似(民權路四段) | J30: 120.18658 | K30: 22.999028 | M30: #179 民權路四段 | N30: 192.7 | P30: 115/06/26 06:01:00 AM | R30: 1999通報單
A31: 51 | B31: 雨水 | C31: 中西區 | D31: 中西區西湖里頂美一街48巷3弄到61巷 | F31: 100以上 | G31: 無法定位，需人工確認 | I31: 未定位 | P31: 115/06/26 06:20:00 AM | R31: 1999通報單
A32: 52 | B32: 雨水 | C32: 中西區 | D32: 中西區民權路四段112巷 | F32: 100以上 | G32: 疑似舊災點(距離相近) | I32: 路名比對近似(民權路四段) | J32: 120.18658 | K32: 22.999028 | M32: #179 民權路四段 | N32: 192.7 | P32: 115/06/26 05:26:00 AM | R32: 1999通報單
A33: 53 | B33: 雨水 | C33: 中西區 | D33: 中西區頂美一街36巷3弄14號 | F33: 100以上 | G33: 無法定位，需人工確認 | I33: 未定位 | P33: 115/06/26 05:31:00 AM | R33: 1999通報單
A34: 54 | B34: 雨水 | C34: 中西區 | D34: 開山路35巷6號(新建案) | E34: 15 | F34: 10-30 | G34: 疑似舊災點 | I34: 路名比對近似(開山路) | J34: 120.20634 | K34: 22.990732 | L34: #150:府中街98巷[中/開山路] | M34: #150 府中街98巷 | N34: 0 | P34: 6/25 2130 | Q34: 6/26凌晨 | R34: 民政局
A35: 55 | B35: 雨水 | C35: 中西區 | D35: 府中街98巷 | E35: 15 | F35: 10-30 | G35: 疑似舊災點 | I35: 路名比對近似(府中街) | J35: 120.20634 | K35: 22.990732 | L35: #150:府中街98巷[高/府中街98巷] | M35: #150 府中街98巷 | N35: 0 | P35: 6/25 2130 | Q35: 6/26凌晨 | R35: 民政局
A36: 56 | B36: 雨水 | C36: 中西區 | D36: 大福街及各巷 | E36: 10 | F36: 0-10 | G36: 無法定位，需人工確認 | I36: 未定位 | P36: 6/26凌晨 | Q36: 6/26凌晨 | R36: 民政局
A37: 57 | B37: 雨水 | C37: 中西區 | D37: 大新街及各巷 | E37: 15 | F37: 10-30 | G37: 疑似舊災點 | I37: 路名比對近似(大新街) | J37: 120.19174 | K37: 23.00023 | L37: #148:臨安路一段周邊巷道[中/大新街] #149:臨安路一段與民權路三段路口[中/大新街] | M37: #148 臨安路一段周邊巷道 | N37: 0 | P37: 6/26凌晨 | Q37: 6/26凌晨 | R37: 民政局
A38: 58 | B38: 雨水 | C38: 中西區 | D38: 西寧街 | E38: 20 | F38: 10-30 | G38: 無法定位，需人工確認 | I38: 未定位 | P38: 6/26凌晨 | Q38: 6/26凌晨 | R38: 民政局
A39: 59 | B39: 雨水 | C39: 中西區 | D39: 濟生街 | E39: 20 | F39: 10-30 | G39: 無法定位，需人工確認 | I39: 未定位 | P39: 6/26凌晨 | Q39: 6/26凌晨 | R39: 民政局
A40: 60 | B40: 雨水 | C40: 中西區 | D40: 臨安路一段 | E40: 20 | F40: 10-30 | G40: 疑似舊災點 | I40: 路名比對近似(臨安路一段) | J40: 120.19174 | K40: 23.00023 | L40: #148:臨安路一段周邊巷道[中/臨安路一段] #149:臨安路一段與民權路三段路口[中/臨安路一段] | M40: #148 臨安路一段周邊巷道 | N40: 0 | P40: 6/26凌晨 | Q40: 6/26凌晨 | R40: 民政局
...

Sheet 歷史災點(108-115)對照
A1: 項次 | B1: 行政區 | C1: 災點名稱 | D1: 事件名稱 | E1: 淹水路段(地點) | F1: 經度X | G1: 緯度Y | H1: 高度(公分) | I1: 本次相符災點序號(名稱或200m內)
A2: 127 | B2: 東區 | C2: 小東路與勝利路口 | D2: 114年丹娜絲颱風 | E2: 小東路與勝利路口 | F2: 120.21858 | G2: 23.001005 | H2: 15
A3: 128 | B3: 東區 | C3: 育樂街 | D3: 112年0907豪雨 | E3: 育樂街 | F3: 120.21479 | G3: 22.995538 | H3: 30 | I3: 507
A4: 129 | B4: 東區 | C4: 榮譽街123巷 | D4: 112年0907豪雨 | E4: 榮譽街123巷 | F4: 120.21861 | G4: 22.975683 | H4: 25
A5: 130 | B5: 東區 | C5: 大同路林森地下道 | D5: 112年0810豪雨 113年0707大雨 113年0715大雨 | E5: 1.大同路林森地下道積水 2.東區大同地下道(向西) | F5: 120.21463 | G5: 22.981847 | H5: 30
A6: 131 | B6: 東區 | C6: 林森路一段153巷 | D6: 地方民意代表陳情(王定宇立委服務處) | E6: 總工交代納入 | F6: 120.23434 | G6: 22.985069 | H6: 0
A7: 132 | B7: 東區 | C7: 中華東路二段133巷 | D7: 地方民意代表陳情(王定宇立委服務處) | E7: 總工交代納入 | F7: 120.21528 | G7: 22.982767 | H7: 0 | I7: 494、496
A8: 133 | B8: 東區 | C8: 虎尾寮水資源回收中心前 | D8: 108年0813豪雨 110年0801豪雨 | E8: 裕義路段(從裕農路至裕孝三街口) 裕義路130-170號 裕德街(北上高速出口下便道) 裕和路與裕和五街 台南交流道北上側車道(裕德街) 東區-虎尾寮水資源回收中心前(編號33) | F8: 120.24883 | G8: 22.98173 | H8: 47 | I8: 489、492、498、499、503、506、513、514
A9: 134 | B9: 東區 | C9: 大同路一段241巷 | D9: 108年0813豪雨 109年0729大雨 112年0907豪雨 | E9: 大同路一段241巷51-77號 大同路一段241巷 | F9: 120.2117 | G9: 22.983228 | H9: 100 | I9: 490、500、504、515
A10: 135 | B10: 東區 | C10: 東成街 | D10: 110年0802大雨 | E10: 東成街富農街交叉口淹水 東成街75號 | F10: 120.23431 | G10: 22.980079 | H10: 20
A11: 136 | B11: 南區 | C11: 灣裡社區低窪地區 | D11: 108年0813豪雨 109年0826豪雨 110年0731豪雨 110年0802大雨 111年0817午後雷陣雨 | E11: 省躬一街 1、灣裡路61、62巷、72巷11號前、88巷、211巷、218巷、222巷、263巷77、93號前、516巷 2.喜樹路222巷至252巷間、288巷、316巷、340巷 | F11: 120.18126 | G11: 22.93595 | H11: 40 | I11: 528、529、530、531、532、535、538、551
A12: 137 | B12: 南區 | C12: 體育路45巷巷口 | D12: 109年0522梅雨 109年0729大雨 | E12: 體育路45巷 體育路（上鶴茶坊與歡喜樓前方） | F12: 120.20734 | G12: 22.979092 | H12: 20
A13: 138 | B13: 南區 | C13: 萬年路167號前路段(台86側車道) | D13: 108年0813豪雨 109年0729大雨 | E13: 萬年路86下道路 萬年路167號前路段(台86側車道) | F13: 120.18657 | G13: 22.935419 | H13: 40 | I13: 521、550
A14: 139 | B14: 北區 | C14: 海安路三段與和緯路二段 | D14: 111年0802豪雨 | E14: 海安路三段與和緯路二段 | F14: 120.20058 | G14: 23.011655 | H14: 30
A15: 140 | B15: 北區 | C15: 小東地下道(編號22感測器) | D15: 110年0730豪雨 110年0731豪雨 110年0801豪雨 110年0802大雨 111年0802豪雨 111年0817午後雷陣雨 112年0611大雨 112年0907豪雨 113年凱米颱風 | E15: 1.小東地下道(編號22感測器) 2.北區前鋒路跟小東路口 | F15: 120.21394 | G15: 23.0016 | H15: 220 | I15: 199、215、247、251、255
A16: 141 | B16: 北區 | C16: 公園北路88巷 | D16: 112年0907豪雨 113年凱米颱風 | E16: 北區公園北路88巷55號旁(編號299) | F16: 120.21071 | G16: 23.005956 | H16: 54.1 | I16: 238、256
A17: 142 | B17: 北區 | C17: 大光里內長榮路五段和公園路交叉口沿線 | D17: 111年0802豪雨 112年0907豪雨 | E17: 1.大光里內長榮路五段和公園路交叉口沿線 2.公園路與長榮路五段交叉口 | F17: 120.2121 | G17: 23.013474 | H17: 20 | I17: 200、204、212、213、217、221、226、240、241、242、243、253
A18: 143 | B18: 北區 | C18: 長榮路五段140號 | D18: 110年0730豪雨 110年0802大雨 | E18: 長榮路五段140號 | F18: 120.22012 | G18: 23.012774 | H18: 15 | I18: 200、226、253
A19: 144 | B19: 北區 | C19: 長北街 | D19: 110年0802大雨 112年0907豪雨 113年凱米颱風 | E19: 1.長北街積水約15公分 2.西門路三段公園北路156號 3.臺南市北區長北街186號至212號一帶、公園北路、公園北路、西門路三段、長北街 | F19: 120.20544 | G19: 23.004832 | H19: 20 | I19: 238、256
A20: 145 | B20: 中西區 | C20: 海安路二段302巷 | D20: 112年0907豪雨 | E20: 海安路二段302巷 | F20: 120.20596 | G20: 22.996076 | H20: 20.8 | I20: 86
A21: 146 | B21: 中西區 | C21: 六合境清水寺 | D21: 112年0907豪雨 | E21: 1.六合境清水寺 2.民權路近青年路 | F21: 120.20632 | G21: 22.99187 | H21: 25.2 | I21: 25、79、107、108
A22: 147 | B22: 中西區 | C22: 友愛街261號(編號100感測器) | D22: 110年0802大雨 111年0802豪雨 112年0907豪雨 113年0715大雨 114年丹娜絲颱風 | E22: 1.友愛街261號(編號100感測器) 2.友愛街261號(編號301) | F22: 120.19641 | G22: 22.99198 | H22: 18.6 | I22: 80、101、109
A23: 148 | B23: 中西區 | C23: 臨安路一段周邊巷道 | D23: 111年0802豪雨 | E23: 和善街整條街、中華西路二段855號前道路、中華西路、大新街47巷與35巷、臨安路一段與民權路三段附近、民權路三段338號、臨安路一段11號 | F23: 120.19174 | G23: 23.00023 | H23: 30 | I23: 22、26、28、39、41、48、57、60、72、91
A24: 149 | B24: 中西區 | C24: 臨安路一段與民權路三段路口 | D24: 113年0528豪雨 113年0715大雨 113年凱米颱風 114年丹娜絲颱風 115年0608鋒面豪雨暨0611大雷雨 | E24: 1.臨安路跟民權路路口(編號273) 2.中西區臨安路跟民權路口 3.中西區臨安路一段88號前 4.中西區臨安路一段88號、大新街3號 5.中西區大新街3號、5號附近、臨安路與民權路口 6.中西區-中和街22號前(編號27) 7.大新街5號與民權路三段 8.大新街 & 民權路三段 | F24: 120.1897 | G24: 22.998428 | H24: 15.1 | I24: 25、39、48、57、60、72、79、107、110
A25: 150 | B25: 中西區 | C25: 府中街98巷 | D25: 109年0729大雨 112年0907豪雨 114年丹娜絲颱風 115年0608鋒面豪雨暨0611大雷雨 | E25: 1.府中街98巷 2.開山路58號與府中街98巷口 3.中西區-開山路58號與府中街98巷口(編號102) 4.中西區開山路52巷3號 | F25: 120.20634 | G25: 22.990732 | H25: 23.1 | I25: 42、54、55、105
A26: 151 | B26: 仁德區 | C26: 機場路495巷口 | D26: 112年0810豪雨 | E26: 機場路495巷口 | F26: 120.21714 | G26: 22.941258 | H26: 10
A27: 152 | B27: 仁德區 | C27: 德洋路涵洞 | D27: 109年0522梅雨 109年0826豪雨 | E27: 德洋路涵洞 | F27: 120.24883 | G27: 22.951643 | H27: 30
A28: 153 | B28: 仁德區 | C28: 潭稅路橋 | D28: 108年0813豪雨 109年0522梅雨 109年0826豪雨 110年0605豪雨 110年0622豪雨 110年0731豪雨 110年0801豪雨 114年0728大豪雨 115年0608鋒面豪雨暨0611大雷雨 115年0614豪雨 | E28: 保安路潭稅橋積水 保安文賢路與三甲涵洞封路 潭稅橋 仁德區保安路一段 保安路一段39號前 保安路一段39號前(編號14) 仁德區-保安路一段台鐵涵洞(編號12) 潭稅路橋、保安路二段(往潭稅陸橋前) | F28: 120.2326 | G28: 22.931424 | H28: 206 | I28: 140、158、170、187
A29: 154 | B29: 仁德區 | C29: 保安路一段56巷口(編號269) | D29: 112年0613大雨 113年0528豪雨 113年凱米颱風 | E29: 1.從保安路一段獨立拉出來(總工交辦) 2.保安路一段56巷口(編號269) | F29: 120.22542 | G29: 22.924418 | H29: 13.9 | I29: 140、170、187
A30: 155 | B30: 仁德區 | C30: 保安路一段 | D30: 108年0813豪雨 109年0522梅雨 109年0826豪雨 110年0730豪雨 110年0731豪雨 | E30: 保安路105號到二仁路 積水無法通行 保安路一段39號前(編號14) 嘉南藥理科技大學宿舍區 保安路一段56巷 保安路一段39號前(編號14) 保安路一段56巷口(編號269) | F30: 120.22746 | G30: 22.922284 | H30: 30 | I30: 140、170、187
A31: 156 | B31: 仁德區 | C31: 民安路二段德善一、二街口(德糖路口) | D31: 108年0813豪雨 109年0522梅雨 109年0816大雨 109年0826豪雨 111年0810大豪雨 111年0815午後雷陣雨 113年0528豪雨 113年0707大雨 113年0715大雨 113年0721豪雨 113年凱米颱風 113年0806豪雨 113年0809豪雨 | E31: 1.民安路一段265巷、民安路二段99號～165號、德糖路民安宮前 2.民安路二段、德糖路口 3.仁德區-民安路二段德善一、二街口(113之1號前) 4.仁德大排旁邊便道 5.民安路二段與德糖路口(編號107) 6.民安路二段德善一、二街口（113之1號前)(編號237) 7.臨安路跟民權路路口(編號273) 8.中西區臨安路跟民權路口 9.中西區臨安路一段88號前 | F31: 120.25463 | G31: 22.952001 | H31: 40 | I31: 123、136、186、190、191
A32: 157 | B32: 仁德區 | C32: 勝利路71號至58巷 | D32: 110年0802大雨 | E32: 勝利路71號至58巷 | F32: 120.25481 | G32: 22.95878 | H32: 15
A33: 158 | B33: 仁德區 | C33: 新田路 | D33: 109年0826豪雨 111年0810大豪雨 | E33: 新田路 | F33: 120.26375 | G33: 22.955419 | H33: 10 | I33: 186
A34: 159 | B34: 仁德區 | C34: 新田路及民安路二段97巷口 (仁德里義林南路961巷136弄) | D34: 108年0813豪雨 109年0826豪雨 110年盧碧颱風 | E34: 1.新田路196號 2.新田路196號旁便道(民安路二段97巷) 3.新田路及民安路二段97巷口 4.仁德里義林南路961巷136弄 | F34: 120.26372 | G34: 22.953879 | H34: 15 | I34: 186、190、191
A35: 160 | B35: 仁德區 | C35: 中正西路360巷20弄33-39號前 | D35: 110年0802大雨 | E35: 中正西路360巷20弄33-39號前 | F35: 120.21726 | G35: 22.918404 | H35: 15 | I35: 184
A36: 161 | B36: 仁德區 | C36: 忠義二街27號 | D36: 108年0813豪雨 110年0802大雨 | E36: 忠義一街、二街 忠義二街27號 | F36: 120.25774 | G36: 22.978647 | H36: 60
A37: 162 | B37: 仁德區 | C37: 太子路高速公路涵洞(編號23感測器) | D37: 110年0802大雨 111年0802豪雨 112年0907豪雨 113年凱米颱風 113年0806豪雨 114年丹娜絲颱風 | E37: 1.仁德區-太子路高速公路涵洞(編號23) 2.太子路涵洞 | F37: 120.2484 | G37: 22.99074 | H37: 25 | I37: 125、126、176、185
A38: 163 | B38: 仁德區 | C38: 中洲里中洲八街 | D38: 110年0731豪雨 | E38: 中洲里中洲八街 | F38: 120.25104 | G38: 22.910769 | H38: 10 | I38: 163
A39: 164 | B39: 仁德區 | C39: 台86橋下便道(近田厝二街) | D39: 108年0813豪雨 109年0826豪雨 110年盧碧颱風 | E39: 台86北上機車道封閉 中正路2段台86橋下淹水 86快速道路下便道近田厝一街(上崙排水) 上崙排水86便道下 台86橋下近田厝二街東向路 | F39: 120.24285 | G39: 22.943376 | H39: 50 | I39: 111、147、168
A40: 165 | B40: 仁德區 | C40: 二行里二行一路153巷16弄 | D40: 112年0908大雨 113年0528豪雨 113年凱米颱風 115年0608鋒面豪雨暨0611大雷雨 | E40: 二行里二行一路153巷16弄(編號254) | F40: 120.22418 | G40: 22.919963 | H40: 25 | I40: 182
...

Sheet 統計摘要
A1: 1150625豪雨災點 新舊災點初判統計(0707資料,7行政區)
A3: 初判結果 | B3: 筆數
A4: 疑似舊災點 | B4: =COUNTIF(本次災點比對結果!G:G,A4) -> 84
A5: 疑似舊災點(距離相近) | B5: =COUNTIF(本次災點比對結果!G:G,A5) -> 14
A6: 待確認(路名部分相符) | B6: =COUNTIF(本次災點比對結果!G:G,A6) -> 78
A7: 新災點(初判) | B7: =COUNTIF(本次災點比對結果!G:G,A7) -> 68
A8: 無法定位，需人工確認 | B8: =COUNTIF(本次災點比對結果!G:G,A8) -> 120
A9: 合計 | B9: =SUM(B4:B8) -> 364
A11: 深度分級 | B11: 筆數
A12: 0-10 | B12: =COUNTIF(本次災點比對結果!F:F,A12) -> 29
A13: 10-30 | B13: =COUNTIF(本次災點比對結果!F:F,A13) -> 96
A14: 30-50 | B14: =COUNTIF(本次災點比對結果!F:F,A14) -> 33
A15: 50-100 | B15: =COUNTIF(本次災點比對結果!F:F,A15) -> 34
A16: 100以上 | B16: =COUNTIF(本次災點比對結果!F:F,A16) -> 172
A17: 無資料 | B17: =COUNTIF(本次災點比對結果!F:F,A17) -> 0
A19: 行政區 | B19: 本次災點數 | C19: 歷史災點數
A20: 仁德區 | B20: =COUNTIF(本次災點比對結果!C:C,A20) -> 81 | C20: =COUNTIF('歷史災點(108-115)對照'!B:B,A20) -> 24
A21: 東區 | B21: =COUNTIF(本次災點比對結果!C:C,A21) -> 28 | C21: =COUNTIF('歷史災點(108-115)對照'!B:B,A21) -> 9
A22: 中西區 | B22: =COUNTIF(本次災點比對結果!C:C,A22) -> 89 | C22: =COUNTIF('歷史災點(108-115)對照'!B:B,A22) -> 6
A23: 北區 | B23: =COUNTIF(本次災點比對結果!C:C,A23) -> 59 | C23: =COUNTIF('歷史災點(108-115)對照'!B:B,A23) -> 6
A24: 安南區 | B24: =COUNTIF(本次災點比對結果!C:C,A24) -> 51 | C24: =COUNTIF('歷史災點(108-115)對照'!B:B,A24) -> 25
A25: 安平區 | B25: =COUNTIF(本次災點比對結果!C:C,A25) -> 23 | C25: =COUNTIF('歷史災點(108-115)對照'!B:B,A25) -> 5
A26: 南區 | B26: =COUNTIF(本次災點比對結果!C:C,A26) -> 33 | C26: =COUNTIF('歷史災點(108-115)對照'!B:B,A26) -> 3
